{"name": "test_getting_users_list", "status": "broken", "statusDetails": {"message": "pydantic.error_wrappers.ValidationError: 1 validation error for User\nname\n  value is not a valid integer (type=type_error.integer)", "trace": "get_users = <Response [200]>, make_number = 696\n\n    @pytest.mark.production\n    def test_getting_users_list(get_users, make_number):\n>       Response(get_users).assert_status_code(200).validate(User)\n\ntests/users/test_users.py:13: \n_ _ _ _ _ _ _ _ _ _ _ _ _ _ _ _ _ _ _ _ _ _ _ _ _ _ _ _ _ _ _ _ _ _ _ _ _ _ _ _ _ _ _ _ \nsrc/baseclasses/response.py:16: in validate\n    schema.parse_obj(item)\npydantic/main.py:526: in pydantic.main.BaseModel.parse_obj\n    ???\n_ _ _ _ _ _ _ _ _ _ _ _ _ _ _ _ _ _ _ _ _ _ _ _ _ _ _ _ _ _ _ _ _ _ _ _ _ _ _ _ _ _ _ _ \n\n>   ???\nE   pydantic.error_wrappers.ValidationError: 1 validation error for User\nE   name\nE     value is not a valid integer (type=type_error.integer)\n\npydantic/main.py:341: ValidationError"}, "start": 1685117407319, "stop": 1685117407320, "uuid": "1f08ffff-1368-490c-9750-3fd538aca9a4", "historyId": "f3a35b35911a2442325e664a2ed974e0", "testCaseId": "f3a35b35911a2442325e664a2ed974e0", "fullName": "tests.users.test_users#test_getting_users_list", "labels": [{"name": "tag", "value": "production"}, {"name": "parentSuite", "value": "tests.users"}, {"name": "suite", "value": "test_users"}, {"name": "host", "value": "dencomp"}, {"name": "thread", "value": "136448-MainThread"}, {"name": "framework", "value": "pytest"}, {"name": "language", "value": "cpython3"}, {"name": "package", "value": "tests.users.test_users"}]}